Workbook

Sheet Semaine_ref_trim
A1: Trimestre | B1: Numero_semaine | C1: DateJ7 | D1: Date_debut_sem_ref | E1: Date_fin_sem_ref | F1: Date1 | G1: Date2 | H1: N_semaine
A2: T2_2024 | B2: Semaine 1 | C2: Monday 1 April 2024 | D2: 45383 | E2: 45389 | F2: 45382 | G2: 45389 | H2: 1
A3: T2_2024 | B3: Semaine 2 | C3: Monday 8 April 2024 | D3: 45390 | E3: 45396 | F3: 45382 | G3: 45389 | H3: 2
A4: T2_2024 | B4: Semaine 3 | C4: Monday 15 April 2024 | D4: 45397 | E4: 45403 | F4: 45396 | G4: 45403 | H4: 3
A5: T2_2024 | B5: Semaine 4 | C5: Monday 22 April 2024 | D5: 45404 | E5: 45410 | F5: 45396 | G5: 45403 | H5: 4
A6: T2_2024 | B6: Semaine 5 | C6: Monday 29 April 2024 | D6: 45411 | E6: 45417 | F6: 45410 | G6: 45417 | H6: 5
A7: T2_2024 | B7: Semaine 6 | C7: Monday 6 May 2024 | D7: 45418 | E7: 45424 | F7: 45410 | G7: 45417 | H7: 6
A8: T2_2024 | B8: Semaine 7 | C8: Monday 13 May 2024 | D8: 45425 | E8: 45431 | F8: 45424 | G8: 45431 | H8: 7
A9: T2_2024 | B9: Semaine 8 | C9: Monday 20 May 2024 | D9: 45432 | E9: 45438 | F9: 45424 | G9: 45431 | H9: 8
A10: T2_2024 | B10: Semaine 9 | C10: Monday 27 May 2024 | D10: 45439 | E10: 45445 | F10: 45438 | G10: 45445 | H10: 9
A11: T2_2024 | B11: Semaine 10 | C11: Monday 3 June 2024 | D11: 45446 | E11: 45452 | F11: 45438 | G11: 45445 | H11: 10
A12: T2_2024 | B12: Semaine 11 | C12: Monday 10 June 2024 | D12: 45453 | E12: 45459 | F12: 45452 | G12: 45459 | H12: 11
A13: T2_2024 | B13: Semaine 12 | C13: Monday 17 June 2024 | D13: 45460 | E13: 45466 | F13: 45452 | G13: 45459 | H13: 12
A14: T2_2024 | B14: Semaine 13 | C14: Monday 24 June 2024 | D14: 45467 | E14: 45473 | F14: 45473 | G14: 45473 | H14: 13
A15: T2_2024 | B15: Semaine 13 | C15: Monday 1 July 2024 | F15: 45473 | G15: 45473 | H15: 13
A16: T3_2024 | B16: Semaine 10 | C16: Monday 10 June 2024 | F16: 45529 | G16: 45536 | H16: 10
A17: T3_2024 | B17: Semaine 7 | C17: Monday 13 May 2024 | F17: 45515 | G17: 45522 | H17: 7
A18: T3_2024 | B18: Semaine 3 | C18: Monday 15 April 2024 | F18: 45487 | G18: 45494 | H18: 3
A19: T3_2024 | B19: Semaine 12 | C19: Monday 17 June 2024 | F19: 45543 | G19: 45550 | H19: 12
A20: T3_2024 | B20: Semaine 8 | C20: Monday 20 May 2024 | F20: 45515 | G20: 45522 | H20: 8
A21: T3_2024 | B21: Semaine 4 | C21: Monday 22 April 2024 | F21: 45487 | G21: 45494 | H21: 4
A22: T3_2024 | B22: Semaine 13 | C22: Monday 24 June 2024 | F22: 45564 | G22: 45564 | H22: 13
A23: T3_2024 | B23: Semaine 9 | C23: Monday 27 May 2024 | F23: 45529 | G23: 45536 | H23: 9
A24: T3_2024 | B24: Semaine 5 | C24: Monday 29 April 2024 | F24: 45501 | G24: 45508 | H24: 5
A25: T3_2024 | B25: Semaine 10 | C25: Monday 3 June 2024 | F25: 45529 | G25: 45536 | H25: 10
A26: T3_2024 | B26: Semaine 6 | C26: Monday 6 May 2024 | F26: 45501 | G26: 45508 | H26: 6
... A47: T3_2024 | B47: Semaine 13 | C47: Monday 23 September 2024 | F47: 45564 | G47: 45564 | H47: 13
A48: T4_2024 | B48: Semaine 1 | C48: Monday 30 September 2024 | D48: 45565 | E48: 45571 | F48: 45564 | G48: 45571 | H48: 1
A49: T4_2024 | B49: Semaine 2 | C49: Monday 7 October 2024 | D49: 45572 | E49: 45578 | F49: 45564 | G49: 45571 | H49: 2
A50: T4_2024 | B50: Semaine 3 | C50: Monday 14 October 2024 | D50: 45579 | E50: 45585 | F50: 45578 | G50: 45585 | H50: 3
A51: T4_2024 | B51: Semaine 4 | C51: Monday 21 October 2024 | D51: 45586 | E51: 45592 | F51: 45578 | G51: 45585 | H51: 4
A52: T4_2024 | B52: Semaine 5 | C52: Monday 28 October 2024 | D52: 45593 | E52: 45599 | F52: 45592 | G52: 45599 | H52: 5
A53: T4_2024 | B53: Semaine 6 | C53: Monday 4 November 2024 | D53: 45600 | E53: 45606 | F53: 45592 | G53: 45599 | H53: 6
A54: T4_2024 | B54: Semaine 7 | C54: Monday 11 November 2024 | D54: 45607 | E54: 45613 | F54: 45606 | G54: 45613 | H54: 7
A55: T4_2024 | B55: Semaine 8 | C55: Monday 18 November 2024 | D55: 45614 | E55: 45620 | F55: 45606 | G55: 45613 | H55: 8
A56: T4_2024 | B56: Semaine 9 | C56: Monday 25 November 2024 | D56: 45621 | E56: 45627 | F56: 45620 | G56: 45627 | H56: 9
A57: T4_2024 | B57: Semaine 10 | C57: Monday 2 December 2024 | D57: 45628 | E57: 45634 | F57: 45620 | G57: 45627 | H57: 10
A58: T4_2024 | B58: Semaine 11 | C58: Monday 9 December 2024 | D58: 45635 | E58: 45641 | F58: 45634 | G58: 45641 | H58: 11
A59: T4_2024 | B59: Semaine 12 | C59: Monday 16 December 2024 | D59: 45642 | E59: 45648 | F59: 45634 | G59: 45641 | H59: 12
... A216: T4_2027 | B216: Semaine 13 | C216: Monday 20 December 2027 | D216: 46741 | E216: 46747 | F216: 46747 | G216: 46747 | H216: 13
...

Sheet Automate_envoie
A1: Trimestre | B1: REGION | C1: Ordre_passage_zd | D1: DateJ7 | E1: Date_debut_sem_ref | F1: Date_fin_sem_ref
A2: T1_2026 | B2: ABIDJAN | C2: 1 | D2: Monday 29 December 2025 | E2: =VLOOKUP(D2,Semaine_ref_trim!$C$1:$E$372,2,FALSE) -> 46020 | F2: =VLOOKUP(D2,Semaine_ref_trim!$C$1:$E$372,3,FALSE) -> 46026
A3: T1_2026 | B3: ABIDJAN | C3: 2 | D3: Monday 5 January 2026 | E3: =VLOOKUP(D3,Semaine_ref_trim!$C$1:$E$372,2,FALSE) -> 46027 | F3: =VLOOKUP(D3,Semaine_ref_trim!$C$1:$E$372,3,FALSE) -> 46033
A4: T1_2026 | B4: ABIDJAN | C4: 3 | D4: Monday 12 January 2026 | E4: =VLOOKUP(D4,Semaine_ref_trim!$C$1:$E$372,2,FALSE) -> 46034 | F4: =VLOOKUP(D4,Semaine_ref_trim!$C$1:$E$372,3,FALSE) -> 46040
A5: T1_2026 | B5: ABIDJAN | C5: 4 | D5: Monday 19 January 2026 | E5: =VLOOKUP(D5,Semaine_ref_trim!$C$1:$E$372,2,FALSE) -> 46041 | F5: =VLOOKUP(D5,Semaine_ref_trim!$C$1:$E$372,3,FALSE) -> 46047
A6: T1_2026 | B6: ABIDJAN | C6: 5 | D6: Monday 26 January 2026 | E6: =VLOOKUP(D6,Semaine_ref_trim!$C$1:$E$372,2,FALSE) -> 46048 | F6: =VLOOKUP(D6,Semaine_ref_trim!$C$1:$E$372,3,FALSE) -> 46054
A7: T1_2026 | B7: ABIDJAN | C7: 6 | D7: Monday 2 February 2026 | E7: =VLOOKUP(D7,Semaine_ref_trim!$C$1:$E$372,2,FALSE) -> 46055 | F7: =VLOOKUP(D7,Semaine_ref_trim!$C$1:$E$372,3,FALSE) -> 46061
A8: T1_2026 | B8: ABIDJAN | C8: 7 | D8: Monday 9 February 2026 | E8: =VLOOKUP(D8,Semaine_ref_trim!$C$1:$E$372,2,FALSE) -> 46062 | F8: =VLOOKUP(D8,Semaine_ref_trim!$C$1:$E$372,3,FALSE) -> 46068
A9: T1_2026 | B9: ABIDJAN | C9: 8 | D9: Monday 16 February 2026 | E9: =VLOOKUP(D9,Semaine_ref_trim!$C$1:$E$372,2,FALSE) -> 46069 | F9: =VLOOKUP(D9,Semaine_ref_trim!$C$1:$E$372,3,FALSE) -> 46075
A10: T1_2026 | B10: ABIDJAN | C10: 9 | D10: Monday 23 February 2026 | E10: =VLOOKUP(D10,Semaine_ref_trim!$C$1:$E$372,2,FALSE) -> 46076 | F10: =VLOOKUP(D10,Semaine_ref_trim!$C$1:$E$372,3,FALSE) -> 46082
A11: T1_2026 | B11: ABIDJAN | C11: 10 | D11: Monday 2 March 2026 | E11: =VLOOKUP(D11,Semaine_ref_trim!$C$1:$E$372,2,FALSE) -> 46083 | F11: =VLOOKUP(D11,Semaine_ref_trim!$C$1:$E$372,3,FALSE) -> 46089
A12: T1_2026 | B12: ABIDJAN | C12: 11 | D12: Monday 9 March 2026 | E12: =VLOOKUP(D12,Semaine_ref_trim!$C$1:$E$372,2,FALSE) -> 46090 | F12: =VLOOKUP(D12,Semaine_ref_trim!$C$1:$E$372,3,FALSE) -> 46096
A13: T1_2026 | B13: ABIDJAN | C13: 12 | D13: Monday 16 March 2026 | E13: =VLOOKUP(D13,Semaine_ref_trim!$C$1:$E$372,2,FALSE) -> 46097 | F13: =VLOOKUP(D13,Semaine_ref_trim!$C$1:$E$372,3,FALSE) -> 46103
A14: T1_2026 | B14: ABIDJAN | C14: 13 | D14: Monday 23 March 2026 | E14: =VLOOKUP(D14,Semaine_ref_trim!$C$1:$E$372,2,FALSE) -> 46104 | F14: =VLOOKUP(D14,Semaine_ref_trim!$C$1:$E$372,3,FALSE) -> 46110
A15: T1_2026 | B15: AUTRES REGIONS | C15: 1 | D15: =D2 -> Monday 29 December 2025 | E15: =VLOOKUP(D15,Semaine_ref_trim!$C$1:$E$372,2,FALSE) -> 46020 | F15: =VLOOKUP(D15,Semaine_ref_trim!$C$1:$E$372,3,FALSE) -> 46026
A16: T1_2026 | B16: AUTRES REGIONS | C16: 2 | D16: =D4 -> Monday 12 January 2026 | E16: =VLOOKUP(D16,Semaine_ref_trim!$C$1:$E$372,2,FALSE) -> 46034 | F16: =VLOOKUP(D16,Semaine_ref_trim!$C$1:$E$372,3,FALSE) -> 46040
A17: T1_2026 | B17: AUTRES REGIONS | C17: 3 | D17: =D6 -> Monday 26 January 2026 | E17: =VLOOKUP(D17,Semaine_ref_trim!$C$1:$E$372,2,FALSE) -> 46048 | F17: =VLOOKUP(D17,Semaine_ref_trim!$C$1:$E$372,3,FALSE) -> 46054
A18: T1_2026 | B18: AUTRES REGIONS | C18: 4 | D18: =D8 -> Monday 9 February 2026 | E18: =VLOOKUP(D18,Semaine_ref_trim!$C$1:$E$372,2,FALSE) -> 46062 | F18: =VLOOKUP(D18,Semaine_ref_trim!$C$1:$E$372,3,FALSE) -> 46068
A19: T1_2026 | B19: AUTRES REGIONS | C19: 5 | D19: =D10 -> Monday 23 February 2026 | E19: =VLOOKUP(D19,Semaine_ref_trim!$C$1:$E$372,2,FALSE) -> 46076 | F19: =VLOOKUP(D19,Semaine_ref_trim!$C$1:$E$372,3,FALSE) -> 46082
A20: T1_2026 | B20: AUTRES REGIONS | C20: 6 | D20: =D12 -> Monday 9 March 2026 | E20: =VLOOKUP(D20,Semaine_ref_trim!$C$1:$E$372,2,FALSE) -> 46090 | F20: =VLOOKUP(D20,Semaine_ref_trim!$C$1:$E$372,3,FALSE) -> 46096
A21: T1_2026 | B21: AUTRES REGIONS | C21: 7 | D21: =D14 -> Monday 23 March 2026 | E21: =VLOOKUP(D21,Semaine_ref_trim!$C$1:$E$372,2,FALSE) -> 46104 | F21: =VLOOKUP(D21,Semaine_ref_trim!$C$1:$E$372,3,FALSE) -> 46110
A22: T2_2026 | B22: ABIDJAN | C22: 1 | D22: Monday 30 March 2026 | E22: =VLOOKUP(D22,Semaine_ref_trim!$C$1:$E$372,2,FALSE) -> 46111 | F22: =VLOOKUP(D22,Semaine_ref_trim!$C$1:$E$372,3,FALSE) -> 46117
A23: T2_2026 | B23: ABIDJAN | C23: 2 | D23: Monday 6 April 2026 | E23: =VLOOKUP(D23,Semaine_ref_trim!$C$1:$E$372,2,FALSE) -> 46118 | F23: =VLOOKUP(D23,Semaine_ref_trim!$C$1:$E$372,3,FALSE) -> 46124
A24: T2_2026 | B24: ABIDJAN | C24: 3 | D24: Monday 13 April 2026 | E24: =VLOOKUP(D24,Semaine_ref_trim!$C$1:$E$372,2,FALSE) -> 46125 | F24: =VLOOKUP(D24,Semaine_ref_trim!$C$1:$E$372,3,FALSE) -> 46131
A25: T2_2026 | B25: ABIDJAN | C25: 4 | D25: Monday 20 April 2026 | E25: =VLOOKUP(D25,Semaine_ref_trim!$C$1:$E$372,2,FALSE) -> 46132 | F25: =VLOOKUP(D25,Semaine_ref_trim!$C$1:$E$372,3,FALSE) -> 46138
A26: T2_2026 | B26: ABIDJAN | C26: 5 | D26: Monday 27 April 2026 | E26: =VLOOKUP(D26,Semaine_ref_trim!$C$1:$E$372,2,FALSE) -> 46139 | F26: =VLOOKUP(D26,Semaine_ref_trim!$C$1:$E$372,3,FALSE) -> 46145
A27: T2_2026 | B27: ABIDJAN | C27: 6 | D27: Monday 4 May 2026 | E27: =VLOOKUP(D27,Semaine_ref_trim!$C$1:$E$372,2,FALSE) -> 46146 | F27: =VLOOKUP(D27,Semaine_ref_trim!$C$1:$E$372,3,FALSE) -> 46152
A28: T2_2026 | B28: ABIDJAN | C28: 7 | D28: Monday 11 May 2026 | E28: =VLOOKUP(D28,Semaine_ref_trim!$C$1:$E$372,2,FALSE) -> 46153 | F28: =VLOOKUP(D28,Semaine_ref_trim!$C$1:$E$372,3,FALSE) -> 46159
A29: T2_2026 | B29: ABIDJAN | C29: 8 | D29: Monday 18 May 2026 | E29: =VLOOKUP(D29,Semaine_ref_trim!$C$1:$E$372,2,FALSE) -> 46160 | F29: =VLOOKUP(D29,Semaine_ref_trim!$C$1:$E$372,3,FALSE) -> 46166
A30: T2_2026 | B30: ABIDJAN | C30: 9 | D30: Monday 25 May 2026 | E30: =VLOOKUP(D30,Semaine_ref_trim!$C$1:$E$372,2,FALSE) -> 46167 | F30: =VLOOKUP(D30,Semaine_ref_trim!$C$1:$E$372,3,FALSE) -> 46173
A31: T2_2026 | B31: ABIDJAN | C31: 10 | D31: Monday 25 May 2026 | E31: =VLOOKUP(D31,Semaine_ref_trim!$C$1:$E$372,2,FALSE) -> 46167 | F31: =VLOOKUP(D31,Semaine_ref_trim!$C$1:$E$372,3,FALSE) -> 46173
A32: T2_2026 | B32: ABIDJAN | C32: 11 | D32: Monday 8 June 2026 | E32: =VLOOKUP(D32,Semaine_ref_trim!$C$1:$E$372,2,FALSE) -> 46181 | F32: =VLOOKUP(D32,Semaine_ref_trim!$C$1:$E$372,3,FALSE) -> 46187
A33: T2_2026 | B33: ABIDJAN | C33: 12 | D33: Monday 15 June 2026 | E33: =VLOOKUP(D33,Semaine_ref_trim!$C$1:$E$372,2,FALSE) -> 46188 | F33: =VLOOKUP(D33,Semaine_ref_trim!$C$1:$E$372,3,FALSE) -> 46194
A34: T2_2026 | B34: ABIDJAN | C34: 13 | D34: Monday 22 June 2026 | E34: =VLOOKUP(D34,Semaine_ref_trim!$C$1:$E$372,2,FALSE) -> 46195 | F34: =VLOOKUP(D34,Semaine_ref_trim!$C$1:$E$372,3,FALSE) -> 46201
A35: T2_2026 | B35: AUTRES REGIONS | C35: 1 | D35: =D22 -> Monday 30 March 2026 | E35: =VLOOKUP(D35,Semaine_ref_trim!$C$1:$E$372,2,FALSE) -> 46111 | F35: =VLOOKUP(D35,Semaine_ref_trim!$C$1:$E$372,3,FALSE) -> 46117
A36: T2_2026 | B36: AUTRES REGIONS | C36: 2 | D36: =D24 -> Monday 13 April 2026 | E36: =VLOOKUP(D36,Semaine_ref_trim!$C$1:$E$372,2,FALSE) -> 46125 | F36: =VLOOKUP(D36,Semaine_ref_trim!$C$1:$E$372,3,FALSE) -> 46131
A37: T2_2026 | B37: AUTRES REGIONS | C37: 3 | D37: =D26 -> Monday 27 April 2026 | E37: =VLOOKUP(D37,Semaine_ref_trim!$C$1:$E$372,2,FALSE) -> 46139 | F37: =VLOOKUP(D37,Semaine_ref_trim!$C$1:$E$372,3,FALSE) -> 46145
A38: T2_2026 | B38: AUTRES REGIONS | C38: 4 | D38: =D28 -> Monday 11 May 2026 | E38: =VLOOKUP(D38,Semaine_ref_trim!$C$1:$E$372,2,FALSE) -> 46153 | F38: =VLOOKUP(D38,Semaine_ref_trim!$C$1:$E$372,3,FALSE) -> 46159
A39: T2_2026 | B39: AUTRES REGIONS | C39: 5 | D39: =D30 -> Monday 25 May 2026 | E39: =VLOOKUP(D39,Semaine_ref_trim!$C$1:$E$372,2,FALSE) -> 46167 | F39: =VLOOKUP(D39,Semaine_ref_trim!$C$1:$E$372,3,FALSE) -> 46173
A40: T2_2026 | B40: AUTRES REGIONS | C40: 6 | D40: =D32 -> Monday 8 June 2026 | E40: =VLOOKUP(D40,Semaine_ref_trim!$C$1:$E$372,2,FALSE) -> 46181 | F40: =VLOOKUP(D40,Semaine_ref_trim!$C$1:$E$372,3,FALSE) -> 46187
...

Sheet label_district
A1: HH1 | B1: label_HH1
A2: 101 | B2: AUTONOME D'ABIDJAN
A3: 102 | B3: AUTONOME DE YAMOUSSOUKRO
A4: 103 | B4: BAS-SASSANDRA
A5: 104 | B5: COMOE
A6: 105 | B6: DENGUELE
A7: 106 | B7: GOH-DJIBOUA
A8: 107 | B8: SASSANDRA-MARAHOUE
A9: 108 | B9: LACS
A10: 109 | B10: LAGUNES
A11: 110 | B11: MONTAGNES
A12: 111 | B12: SAVANES
... A15: 114 | B15: ZANZAN

Sheet label_region
A1: HH2 | B1: label_HH2
A2: 10101 | B2: ABIDJAN
A3: 10916 | B3: AGNEBY-TIASSA
A4: 11319 | B4: BAFING
A5: 11120 | B5: BAGOUE
A6: 10821 | B6: BELIER
A7: 11322 | B7: BERE
A8: 11423 | B8: BOUNKANI
A9: 11018 | B9: CAVALLY
A10: 10524 | B10: FOLON
A11: 11204 | B11: GBEKE
A12: 10325 | B12: GBOKLE
A13: 10617 | B13: GÔH
... A34: 10207 | B34: YAMOUSSOUKRO

Sheet label_departement
A1: HH3 | B1: label_HH3
A2: 10101002 | B2: ABIDJAN
A3: 10207049 | B3: YAMOUSSOUKRO
A4: 10207072 | B4: ATTIEGOUAKRO
A5: 10309037 | B5: SAN-PEDRO
A6: 10309042 | B6: TABOU
A7: 10325038 | B7: SASSANDRA
A8: 10325077 | B8: FRESCO
A9: 10331041 | B9: SOUBRE
A10: 10331078 | B10: GUEYO
A11: 10331096 | B11: BUYO
A12: 10331104 | B12: MEAGUI
... A112: 11423091 | B112: TEHINI
C114: .

Sheet label_sp
A1: HH4 | B1: label_HH4
A2: 1010100202 | B2: ANYAMA
A3: 1010100203 | B3: BINGERVILLE
A4: 1010100204 | B4: BROFODOUME
A5: 1010100205 | B5: SONGON
A6: 1010100211 | B6: ABOBO
A7: 1010100212 | B7: ADJAME
A8: 1010100213 | B8: ATTECOUBE
A9: 1010100214 | B9: COCODY
A10: 1010100215 | B10: KOUMASSI
A11: 1010100216 | B11: MARCORY
A12: 1010100217 | B12: PLATEAU
... A520: 1142309103 | B520: TOUGBO
B522: .

Sheet Feuil1
C1: Monday 10 February 2025 | D1: 1 | E1: 45704 | F1: 45711 | L1: DateJ7 | M1: Date1 | N1: Date2
C2: Monday 10 March 2025 | D2: 2 | E2: 45732 | F2: 45739 | L2: Monday 30 December 2024 | M2: =VLOOKUP(L2,$C$1:$F$13,3,FALSE) -> 45662 | N2: =VLOOKUP(L2,$C$1:$F$13,4,FALSE) -> 45669
C3: Monday 13 January 2025 | D3: 3 | E3: 45676 | F3: 45683 | L3: Monday 6 January 2025 | M3: =VLOOKUP(L3,$C$1:$F$13,3,FALSE) -> 45662 | N3: =VLOOKUP(L3,$C$1:$F$13,4,FALSE) -> 45669
C4: Monday 17 February 2025 | D4: 4 | E4: 45704 | F4: 45711 | L4: Monday 13 January 2025 | M4: =VLOOKUP(L4,$C$1:$F$13,3,FALSE) -> 45676 | N4: =VLOOKUP(L4,$C$1:$F$13,4,FALSE) -> 45683
C5: Monday 17 March 2025 | D5: 5 | E5: 45732 | F5: 45739 | L5: Monday 20 January 2025 | M5: =VLOOKUP(L5,$C$1:$F$13,3,FALSE) -> 45676 | N5: =VLOOKUP(L5,$C$1:$F$13,4,FALSE) -> 45683
C6: Monday 20 January 2025 | D6: 6 | E6: 45676 | F6: 45683 | L6: Monday 27 January 2025 | M6: =VLOOKUP(L6,$C$1:$F$13,3,FALSE) -> 45690 | N6: =VLOOKUP(L6,$C$1:$F$13,4,FALSE) -> 45697
C7: Monday 24 February 2025 | D7: 7 | E7: 45718 | F7: 45725 | L7: Monday 3 February 2025 | M7: =VLOOKUP(L7,$C$1:$F$13,3,FALSE) -> 45690 | N7: =VLOOKUP(L7,$C$1:$F$13,4,FALSE) -> 45697
C8: Monday 24 March 2025 | D8: 8 | E8: 45746 | F8: 45746 | L8: Monday 10 February 2025 | M8: =VLOOKUP(L8,$C$1:$F$13,3,FALSE) -> 45704 | N8: =VLOOKUP(L8,$C$1:$F$13,4,FALSE) -> 45711
C9: Monday 27 January 2025 | D9: 9 | E9: 45690 | F9: 45697 | L9: Monday 17 February 2025 | M9: =VLOOKUP(L9,$C$1:$F$13,3,FALSE) -> 45704 | N9: =VLOOKUP(L9,$C$1:$F$13,4,FALSE) -> 45711
C10: Monday 3 February 2025 | D10: 10 | E10: 45690 | F10: 45697 | L10: Monday 24 February 2025 | M10: =VLOOKUP(L10,$C$1:$F$13,3,FALSE) -> 45718 | N10: =VLOOKUP(L10,$C$1:$F$13,4,FALSE) -> 45725
C11: Monday 3 March 2025 | D11: 11 | E11: 45718 | F11: 45725 | L11: Monday 3 March 2025 | M11: =VLOOKUP(L11,$C$1:$F$13,3,FALSE) -> 45718 | N11: =VLOOKUP(L11,$C$1:$F$13,4,FALSE) -> 45725
C12: Monday 30 December 2024 | D12: 12 | E12: 45662 | F12: 45669 | L12: Monday 10 March 2025 | M12: =VLOOKUP(L12,$C$1:$F$13,3,FALSE) -> 45732 | N12: =VLOOKUP(L12,$C$1:$F$13,4,FALSE) -> 45739
C13: Monday 6 January 2025 | D13: 13 | E13: 45662 | F13: 45669 | L13: Monday 17 March 2025 | M13: =VLOOKUP(L13,$C$1:$F$13,3,FALSE) -> 45732 | N13: =VLOOKUP(L13,$C$1:$F$13,4,FALSE) -> 45739
A14: STXT(B2;4;NBCAR(B2)-3) | L14: Monday 24 March 2025 | M14: =VLOOKUP(L14,$C$1:$F$13,3,FALSE) -> 45746 | N14: =VLOOKUP(L14,$C$1:$F$13,4,FALSE) -> 45746
A15: SI(B2="Semaine 1";1;SI(B2="Semaine 2";2;SI(B2="Semaine 3";3;SI(B2="Semaine 4"; 4; SI(B2="Semaine 5";5;SI(B2="Semaine 6";6;SI(B2="Semaine 7";7;SI(B2="Semaine 8";8;SI(B2="Semaine 9";9;SI(B2="Semaine 10";10;SI(B2="Semaine 11";11;SI(B2="Semaine 12";12;SI(B2="Semaine 13";13)))))))))))))
A19: Voici le prompt que j'ai tapé pour determiner les variables Date1 et Date2. | B19: Voici le prompte que j'ai tapé pour avoir DateJ7 | C19: Voici le prompte que j'ai tapé pour avoir les dates debut et fin des semaines de references
A20: Je veux que tu analyse les tableaux de T1-2025 suivant et me dise a quoi sert Date1 et Date2. Mais en guise d'indice, sur les 13 semaine qui compose le T1-2025, nous avons essayer de definir des date telle que 2 semaine forme un groupe de durée encadré par Date1 et Dat2. Date1 et Date 2 represente : Date1 : est le jour de dimanche qui precedde le lundi de la semaine 1 Date2 : est le jour de dimanche qui precedde le lundi de la semaine 2 Mais pour rappelle : les ). Mais la semaine 13 , on simule la date d'une 14ieme semaine (qui est le lundi de la 1ere semaine du 1er mois du trimestre prochain; et nous prenons le dimanche de cette qui precede le lundi de cette 14ieme semaine du trimestre prochain pour constitue la Date1 et Date2 de la semaine 13) DateJ7 Date1 Date2 Monday 30 December 2024 05/01/2025 12/01/2025 Monday 6 January 2025 05/01/2025 12/01/2025 Monday 13 January 2025 19/01/2025 26/01/2025 Monday 20 January 2025 19/01/2025 26/01/2025 Monday 27 January 2025 02/02/2025 09/02/2025 Monday 3 February 2025 02/02/2025 09/02/2025 Monday 10 February 2025 16/02/2025 23/02/2025 Monday 17 February 2025 16/02/2025 23/02/2025 Monday 24 February 2025 02/03/2025 09/03/2025 Monday 3 March 2025 02/03/2025 09/03/2025 Monday 10 March 2025 16/03/2025 23/03/2025 Monday 17 March 2025 16/03/2025 23/03/2025 Monday 24 March 2025 30/03/2025 30/03/2025 | B20: Le trimestre T4-2025 est subdivisé en 13 semaines, si l'on considère que la semaine par du lundi au dimanche. Je veux que tu sudivise la semaine du T4-2025 est 13 semaines en precisant : Semaine 1 : lundi 29 septembre 2025 - dimanche 5 octobre 2025 | C20: Sur la base de ta comprension je souhaite que tu crée des Date1 et Date2 sous le format 05/01/2025 pour les 13 semaines que je vais te donné; Je veux aussi que tu cree deux colonnes ou tu donnera la date debut du lundi en format 05/01/2025 et une colonnes de date de fin du dimanche en en format 05/01/2025 pour chacune des 13 semaines du T4-2027 Monday 27 September 2027 Monday 4 October 2027 Monday 11 October 2027 Monday 18 October 2027 Monday 25 October 2027 Monday 1 November 2027 Monday 8 November 2027 Monday 15 November 2027 Monday 22 November 2027 Monday 29 November 2027 Monday 6 December 2027 Monday 13 December 2027 Monday 20 December 2027
